<?xml version="1.0"?>

<!--
License: Apache 2.0. See LICENSE file in root directory.
Copyright(c) 2017 PAL Robotics, S.L. All Rights Reserved

This is the Gazebo URDF model for the Intel RealSense D435 camera
-->
  
<robot xmlns:xacro="http://ros.org/wiki/xacro">
  
  <xacro:macro name="gazebo_d435" params="camera_name reference_link topics_ns depth_optical_frame color_optical_frame infrared1_optical_frame infrared2_optical_frame publish_pointcloud:=true" >

    <!-- Load parameters to model's main link-->
    <xacro:property name="deg_to_rad" value="0.01745329251994329577" />
    <gazebo reference="${reference_link}">
      <self_collide>0</self_collide>
      <enable_wind>0</enable_wind>
      <kinematic>0</kinematic>
      <gravity>1</gravity>
      <!--<mu>1</mu>-->
      <mu2>1</mu2>
      <fdir1>0 0 0</fdir1>
      <!--<slip1>0</slip1>
      <slip2>0</slip2>-->
      <kp>1e+13</kp>
      <kd>1</kd>
      <!--<max_vel>0.01</max_vel>
      <min_depth>0</min_depth>-->
      <sensor name="${camera_name}color" type="camera">
        <camera name="${camera_name}">
          <horizontal_fov>${69.4*deg_to_rad}</horizontal_fov>
          <image>
            <width>640</width>
            <height>480</height>
            <format>RGB_INT8</format>
          </image>
          <clip>
            <near>0.1</near>
            <far>100</far>
          </clip>
          <noise>
            <type>gaussian</type>
            <mean>0.0</mean>
            <stddev>0.007</stddev>
          </noise>
        </camera>
        <always_on>1</always_on>
        <update_rate>90</update_rate>
        <visualize>1</visualize>
      </sensor>
      <sensor name="${camera_name}ired1" type="camera">
        <camera name="${camera_name}">
          <horizontal_fov>${85.2*deg_to_rad}</horizontal_fov>
          <image>
            <width>1280</width>
            <height>720</height>
            <format>RGB_INT8</format>
          </image>
          <clip>
            <near>0.1</near>
            <far>100</far>
          </clip>
          <noise>
            <type>gaussian</type>
            <mean>0.0</mean>
            <stddev>0.05</stddev>
          </noise>
        </camera>
        <always_on>1</always_on>
        <update_rate>90</update_rate>
        <visualize>0</visualize>
      </sensor>
      <sensor name="${camera_name}ired2" type="camera">
        <camera name="${camera_name}">
          <horizontal_fov>${85.2*deg_to_rad}</horizontal_fov>
          <image>
            <width>1280</width>
            <height>720</height>
            <format>RGB_INT8</format>
          </image>
          <clip>
            <near>0.1</near>
            <far>100</far>
          </clip>
          <noise>
            <type>gaussian</type>
            <mean>0.0</mean>
            <stddev>0.05</stddev>
          </noise>
        </camera>
        <always_on>1</always_on>
        <update_rate>90</update_rate>
        <visualize>0</visualize>
      </sensor>
      <sensor name="${camera_name}depth" type="depth">
        <camera name="${camera_name}">
          <horizontal_fov>${85.2*deg_to_rad}</horizontal_fov>
          <image>
            <width>1280</width>
            <height>720</height>
          </image>
          <clip>
            <near>0.1</near>
            <far>100</far>
          </clip>
          <noise>
            <type>gaussian</type>
            <mean>0.0</mean>
            <stddev>0.100</stddev>
          </noise>
        </camera>
        <always_on>1</always_on>
        <update_rate>90</update_rate>
        <visualize>0</visualize>
      </sensor>
    </gazebo>

    <gazebo>
      <plugin name="${topics_ns}" filename="librealsense_gazebo_plugin.so">
        <prefix>${camera_name}</prefix>
        <depthUpdateRate>90.0</depthUpdateRate>
        <colorUpdateRate>90.0</colorUpdateRate>
        <infraredUpdateRate>90.0</infraredUpdateRate>
        <depthTopicName>depth/image_raw</depthTopicName>
        <depthCameraInfoTopicName>depth/camera_info</depthCameraInfoTopicName>
        <colorTopicName>color/image_raw</colorTopicName>
        <colorCameraInfoTopicName>color/camera_info</colorCameraInfoTopicName>
        <infrared1TopicName>infra1/image_raw</infrared1TopicName>
        <infrared1CameraInfoTopicName>infra1/camera_info</infrared1CameraInfoTopicName>
        <infrared2TopicName>infra2/image_raw</infrared2TopicName>
        <infrared2CameraInfoTopicName>infra2/camera_info</infrared2CameraInfoTopicName>
        <colorOpticalframeName>${color_optical_frame}</colorOpticalframeName>
        <depthOpticalframeName>${depth_optical_frame}</depthOpticalframeName>
        <infrared1OpticalframeName>${infrared1_optical_frame}</infrared1OpticalframeName>
        <infrared2OpticalframeName>${infrared2_optical_frame}</infrared2OpticalframeName>
        <rangeMinDepth>0.2</rangeMinDepth>
        <rangeMaxDepth>10.0</rangeMaxDepth>
        <pointCloud>${publish_pointcloud}</pointCloud>
        <pointCloudTopicName>depth/color/points</pointCloudTopicName>
        <pointCloudCutoff>0.25</pointCloudCutoff>
        <pointCloudCutoffMax>9.0</pointCloudCutoffMax>
      </plugin>
    </gazebo>
    
    
   <joint name="link_chassis_base_link" type="fixed">
    <origin rpy="0 0 0" xyz="-0.25 0 -0.08"/>
    <child link="link_chassis" />
    <parent link="base_link"/>
    <axis rpy="0 0 0" xyz="0 1 0"/>
    <limit effort="10000" velocity="1000"/>
    <joint_properties damping="1.0" friction="1.0" />
  </joint>  
     <link name="link_chassis">
    <!-- pose and inertial -->
    <pose>0 0 0.1 0 0 0</pose>
    
    <inertial>
      <mass value="5"/>
      <origin rpy="0 0 0" xyz="0 0 0.1"/>
      <inertia ixx="0.0395416666667" ixy="0" ixz="0" iyy="0.106208333333" iyz="0" izz="0.106208333333"/>
    </inertial>
    
    <collision name="collision_chassis">
      <geometry>
        <box size="0.5 0.3 0.07"/>
      </geometry>
    </collision>
    
    <visual>
      <origin rpy="0 0 0" xyz="0 0 0"/>
      <geometry>
        <box size="0.5 0.3 0.07"/>
      </geometry>
      <material name="blue"/>
    </visual>
    
    <!-- caster front -->
    <collision name="caster_front_collision">
      <origin rpy=" 0 0 0" xyz="0.35 0 -0.05"/>
      <geometry>
        <sphere radius="0.05"/>
      </geometry>
      <surface>
        <friction>
          <ode>
            <mu>0</mu>
            <mu2>0</mu2>
            <slip1>1.0</slip1>
            <slip2>1.0</slip2>
          </ode>
        </friction>
      </surface>
    </collision>
    <visual name="caster_front_visual">
      <origin rpy=" 0 0 0" xyz="0.2 0 -0.05"/>
      <geometry>
        <sphere radius="0.05"/>
      </geometry>
    </visual>
    </link>
  
  <!-- Create wheel right -->  
    
  <link name="link_right_wheel">    
    <inertial>
      <mass value="0.2"/>
      <origin rpy="0 1.5707 1.5707" xyz="0 0 0"/>
      <inertia ixx="0.00052666666" ixy="0" ixz="0" iyy="0.00052666666" iyz="0" izz="0.001"/>
    </inertial>
    
    <collision name="link_right_wheel_collision">
      <origin rpy="0 1.5707 1.5707" xyz="0 0 0" />
      <geometry>
        <cylinder length="0.04" radius="0.1"/>
      </geometry>
    </collision>
    
    <visual name="link_right_wheel_visual">
      <origin rpy="0 1.5707 1.5707" xyz="0 0 0"/>
      <geometry>
        <cylinder length="0.04" radius="0.1"/>
      </geometry>      
    </visual>
    
  </link>
    
  <!--   Joint for right wheel  -->
  <joint name="joint_right_wheel" type="continuous">
    <origin rpy="0 0 0" xyz="-0.05 0.15 0"/>
    <child link="link_right_wheel" />
    <parent link="link_chassis"/>
    <axis rpy="0 0 0" xyz="0 1 0"/>
    <limit effort="10000" velocity="1000"/>
    <joint_properties damping="1.0" friction="1.0" />
  </joint>  
    
  <!-- Left Wheel link -->
    
  <link name="link_left_wheel">    
    <inertial>
      <mass value="0.2"/>
      <origin rpy="0 1.5707 1.5707" xyz="0 0 0"/>
      <inertia ixx="0.00052666666" ixy="0" ixz="0" iyy="0.00052666666" iyz="0" izz="0.001"/>
    </inertial>
    
    <collision name="link_left_wheel_collision">
      <origin rpy="0 1.5707 1.5707" xyz="0 0 0" />
      <geometry>
        <cylinder length="0.04" radius="0.1"/>
      </geometry>
    </collision>
    
    <visual name="link_left_wheel_visual">
      <origin rpy="0 1.5707 1.5707" xyz="0 0 0"/>
      <geometry>
        <cylinder length="0.04" radius="0.1"/>
      </geometry>      
    </visual>
    
  </link>
    
  <!--   Joint for right wheel  -->
  <joint name="joint_left_wheel" type="continuous">
    <origin rpy="0 0 0" xyz="-0.05 -0.15 0"/>
    <child link="link_left_wheel" />
    <parent link="link_chassis"/>
    <axis rpy="0 0 0" xyz="0 1 0"/>
    <limit effort="10000" velocity="1000"/>
    <joint_properties damping="1.0" friction="1.0" />
  </joint>  
  
    <gazebo>
    <plugin filename="libgazebo_ros_diff_drive.so" name="differential_drive_controller">
      <alwaysOn>true</alwaysOn>
      <updateRate>20</updateRate>
      <leftJoint>joint_left_wheel</leftJoint>
      <rightJoint>joint_right_wheel</rightJoint>
      <wheelSeparation>0.4</wheelSeparation>
      <wheelDiameter>0.2</wheelDiameter>
      <torque>0.1</torque>
      <commandTopic>cmd_vel</commandTopic>
      <odometryTopic>odom</odometryTopic>
      <odometryFrame>odom</odometryFrame>
      <robotBaseFrame>base_link</robotBaseFrame>
    </plugin>
  </gazebo>
  
   <!-- joint name="hokuyo_joint" type="fixed">
    <axis xyz="0 1 0" />
    <origin xyz="0 0 0.13" rpy="0 0 0"/>
    <parent link="link_chassis"/>
    <child link="hokuyo_link"/>
   </joint -->
   
    <!-- Hokuyo Laser -->
  <!--link name="hokuyo_link">
    <collision>
      <origin xyz="0 0 0" rpy="0 0 0"/>
      <geometry>
    <box size="0.1 0.1 0.1"/>
      </geometry>
    </collision>

    <visual>
      <origin xyz="0 0 0" rpy="0 0 0"/>
      <geometry>
        <box size="0.1 0.1 0.1"/>
      </geometry>
    </visual>

    <inertial>
      <mass value="1e-5" />
      <origin xyz="0 0 0" rpy="0 0 0"/>
      <inertia ixx="1e-6" ixy="0" ixz="0" iyy="1e-6" iyz="0" izz="1e-6" />
    </inertial>
  </link -->
  
  <!--
  <gazebo reference="hokuyo_link">
    <sensor type="gpu_ray" name="head_hokuyo_sensor">
      <pose>0 0 0 0 0 0</pose>
      <visualize>false</visualize>
      <update_rate>40</update_rate>
      <ray>
        <scan>
          <horizontal>
            <samples>720</samples>
            <resolution>1</resolution>
            <min_angle>-1.570796</min_angle>
            <max_angle>1.570796</max_angle>
          </horizontal>
        </scan>
        <range>
          <min>0.10</min>
          <max>30.0</max>
          <resolution>0.01</resolution>
        </range>
        <noise>
          <type>gaussian</type>
          <mean>0.0</mean>
          <stddev>0.01</stddev>
        </noise>
      </ray>
      <plugin name="gazebo_ros_head_hokuyo_controller" filename="libgazebo_ros_gpu_laser.so">
        <topicName>/scan</topicName>
        <frameName>hokuyo_link</frameName>
      </plugin>
    </sensor>
  </gazebo >
  -->  

  

  </xacro:macro>
</robot>
